<?xml version="1.0"?>
<robot name="simrobot">
    <material name="black">
        <color rgba="0 0 0 1"/>
    </material>
    <material name="white">
        <color rgba="1 1 1 1"/>
    </material>
    <material name="blue">
        <color rgba="0.0 0.0 0.8 1.0"/>
    </material>
    <material name="yellow">
        <color rgba="1.0 0.4 0.0 1.0"/>
    </material>
    <material name="gray">
        <color rgba="0.75 0.75 0.75 1.0"/>
    </material>


    <link name="base_footprint"/>

    <link name="base_link">
        <visual>
            <origin xyz="0 0 0" rpy="0 0 0"/>
            <geometry>
                <mesh filename="package://robot_description/meshes/base_link.dae"/>
            </geometry>
            <material name="black"/>
        </visual>
        <inertial>
            <origin xyz="-0.036932 -3.6183E-09 5.4279E-05" rpy="0 0 0"/>
            <mass value="0.62461"/>
            <inertia ixx="0.002014" ixy="3.2092E-10" ixz="-5.0446E-05" iyy="0.0023871" iyz="5.0493E-08" izz="0.0027336"/>
        </inertial>
        <collision>
            <origin xyz="0 0 0" rpy="0 0 0"/>
            <geometry>
                <mesh filename="package://robot_description/meshes/base_link.dae"/>
            </geometry>
        </collision>
    </link>
    <joint name="bash_link_joint" type="fixed">
        <axis rpy="0 0 0" xyz="0 0 0"/>
        <origin rpy="0 0 0" xyz="0 0 0.0565"/>
        <parent link="base_footprint"/>
        <child link="base_link"/>
    </joint>

    <link name="right_wheel">
        <visual>
            <origin xyz="0 0 0" rpy="0 0 0"/>
            <geometry>
                <mesh filename="package://robot_description/meshes/right_wheel.dae"/>
            </geometry>
            <material name="white"/>
        </visual>
        <inertial>
            <origin xyz="0 -0.0033767 0" rpy="0 0 0"/>
            <mass value="0.052928"/>
            <inertia ixx="2.1269E-05" ixy="-7.7807E-22" ixz="2.6095E-21" iyy="3.6821E-05" iyz="-1.6034E-21" izz="2.1269E-05"/>
        </inertial>
        <collision>
            <origin xyz="0 0 0" rpy="0 0 0"/>
            <geometry>
                <mesh filename="package://robot_description/meshes/right_wheel.dae"/>
            </geometry>
        </collision>
    </link>
    <joint name="right_wheel_joint" type="continuous">
        <axis xyz="0 1 0"/>
        <origin rpy="-7.0774E-16 -6.9389E-18 9.8142E-17" xyz="0 -0.0775 -0.024"/>
        <limit effort="0.5" velocity="100"/>
        <dynamics damping="0.0" friction="0.5"/>
        <parent link="base_link"/>
        <child link="right_wheel"/>
    </joint>

    <link name="left_wheel">
        <visual>
            <origin xyz="0 0 0" rpy="0 0 0"/>
            <geometry>
                <mesh filename="package://robot_description/meshes/left_wheel.dae"/>
            </geometry>
            <material name="white"/>
        </visual>
        <inertial>
            <origin xyz="0 0.0033767 0" rpy="0 0 0"/>
            <mass value="0.052928"/>
            <inertia ixx="2.1269E-05" ixy="-8.5384E-22" ixz="-1.5763E-21" iyy="3.6821E-05" iyz="1.4005E-21" izz="2.1269E-05"/>
        </inertial>
        <collision>
            <origin xyz="0 0 0" rpy="0 0 0"/>
            <geometry>
                <mesh filename="package://robot_description/meshes/left_wheel.dae"/>
            </geometry>
        </collision>
    </link>
    <joint name="left_wheel_joint" type="continuous">
        <axis xyz="0 1 0"/>
        <origin rpy="-7.0774E-16 -6.9389E-18 9.8142E-17" xyz="0 0.0775 -0.024"/>
        <limit effort="0.5" velocity="100"/>
        <dynamics damping="0.0" friction="0.5"/>
        <parent link="base_link"/>
        <child link="left_wheel"/>
    </joint> 

    <!--imu-->
    <link name="imu_link">
        <inertial>
            <mass value="1e-5"/>
            <origin rpy="0 0 0" xyz="0 0 0"/>
            <inertia ixx="1e-6" ixy="0" ixz="0" iyy="1e-6" iyz="0" izz="1e-6"/>
        </inertial>
         <visual>
            <origin rpy="0 0 0" xyz="0 0 0"/>
            <geometry>
                <box size="0.015 0.015 0.005"/>
            </geometry>
            <material name="blue"/>
        </visual>
        <collision>
            <origin rpy="0 0 0" xyz="0 0 0"/>
            <geometry>
                <box size="0.015 0.015 0.005"/>
            </geometry>
        </collision>
    </link>
    <joint name="imu_link_joint" type="fixed">
        <axis rpy="0 0 0" xyz="0 0 0"/>
        <origin xyz="-0.1 0 0.003"/>
        <parent link="base_link"/>
        <child link="imu_link"/>
    </joint>

    <!--lidar-->
    <link name="rplidar">
        <inertial>
            <mass value="1e-5"/>
            <origin rpy="0 0 0" xyz="0 0 0"/>
            <inertia ixx="1e-6" ixy="0" ixz="0" iyy="1e-6" iyz="0" izz="1e-6"/>
        </inertial>
        <visual>
            <origin rpy="0 0 0" xyz="0 0 0"/>
            <geometry>
                <mesh filename="package://robot_description/meshes/rplidar.dae"/>
            </geometry>
            <material name="blue"/>
        </visual>
        <collision>
            <origin rpy="0 0 0" xyz="0 0 0"/>
            <geometry>
                <mesh filename="package://robot_description/meshes/rplidar.dae"/> 
            </geometry>
        </collision>
    </link>
    <joint name="rplidar_joint" type="fixed">
        <axis xyz="0 1 0"/>
        <origin xyz="0 0 0.07"/>
        <parent link="base_link"/>
        <child link="rplidar"/>
    </joint>

    <!--sonar-->
    <link name="sonar_1">
        <inertial>
            <mass value="1e-5"/>
            <origin rpy="0 0 0" xyz="0 0 0"/>
            <inertia ixx="1e-6" ixy="0" ixz="0" iyy="1e-6" iyz="0" izz="1e-6"/>
        </inertial>
         <visual>
            <origin rpy="0 0 0" xyz="0 0 0"/>
            <geometry>
                <box size="0.015 0.04 0.02"/>
            </geometry>
            <material name="my_green">
                <color rgba="0.24 0.56 0.26 1.0"/>
            </material>
        </visual>
        <collision>
            <origin rpy="0 0 0" xyz="0 0 0"/>
            <geometry>
                <box size="0.015 0.04 0.02"/>
            </geometry>
        </collision>
    </link>
    <joint name="sonar_1_joint" type="fixed">
        <axis xyz="0 1 0"/>
        <origin xyz="0.045 0 0.0095"/>
        <parent link="base_link"/>
        <child link="sonar_1"/>
    </joint>

    <!-- Camera -->
    <link name="kinect">
        <inertial>
            <mass value="1e-5" />
            <origin xyz="0 0 0" rpy="0 0 0"/>
            <inertia ixx="1e-6" ixy="0" ixz="0" iyy="1e-6" iyz="0" izz="1e-6" />
        </inertial>
        <visual>
            <origin xyz="0 0 0" rpy="0 0 0"/>
            <geometry>
                <!--<mesh filename="package://robot_description/meshes/xtion_pro_camera.dae" />-->
                <mesh filename="package://robot_description/meshes/realsense.dae" />
            </geometry>
        </visual>
        <collision>
            <origin xyz="0 0 0" rpy="0 0 0"/>
            <geometry>
                <mesh filename="package://robot_description/meshes/realsense.dae" />
            </geometry>
        </collision>
    </link>
    <joint name="kinect" type="fixed">
        <axis xyz="0 1 0" />
        <origin xyz="-0.055 0 0.155" rpy="0 0 0"/>
        <parent link="base_link"/>
        <child link="kinect"/>
    </joint>
    <link name="kinect_cylinder">
        <inertial>
            <mass value="1e-5"/>
            <origin rpy="0 0 0" xyz="0 0 0"/>
            <inertia ixx="1e-6" ixy="0" ixz="0" iyy="1e-6" iyz="0" izz="1e-6"/>
        </inertial>
         <visual>
            <origin rpy="0 0 0" xyz="0 0 0"/>
            <geometry>
                <cylinder length="0.1" radius="0.0065"/>
            </geometry>
            <material name="gray"/>
        </visual>
        <collision>
            <origin rpy="0 0 0" xyz="0 0 0"/>
            <geometry>
                <cylinder length="0.11" radius="0.0065"/>
            </geometry>
        </collision>
    </link>
    <joint name="kinect_cylinder_joint" type="fixed">
        <axis xyz="0 1 0"/>
        <origin xyz="-0.05 0 0.11"/>
        <parent link="base_link"/>
        <child link="kinect_cylinder"/>
    </joint>


</robot>